Workbook

Sheet Trim Take Off
B2: Job | C2: GREENE
B3: Customer | C3: BAR 17
B5: TAKE OFF
B6: ITEM | C6: LF | P6: Start by filling out the Job and Customer names, then fill in the information in the Take Off Table
B7: EXT WALL | C7: 150 | P7: Total lf of exterior wall (to receive base trim)
B8: INT WALL | C8: 100 | P8: Total lf of interior walls (to receive base trim)
B9: EXT DOORS | C9: 3 | P9: Total EXT Doors, double doors count as 2
B10: SLIDERS | C10: 3 | P10: Total Sliders, extra large count as 2
B11: WINDOWS | C11: 15 | P11: Total windows
B12: INT DOORS | C12: 15 | P12: Total interior swing doors
B13: POCKET DOOR | C13: 2 | P13: Total pocket, bi fold, or bi pass doors
B14: BARN DOOR/WRAPPED OPENING | C14: 1 | P14: Total barn doors or wrapped openings
B15: DOOR HEIGHT | C15: 80 | P15: Door height, if door height changes either do 2 take offs, or adjust counts proportionally
B16: STYLE | C16: CRAFTSMAN | P16: (an 80" is 84% of a 96" door, 84" door is 88% of a 96" door)
B17: PROFILE | C17: CUSTOM | P17: Style will change the LF outputs based on assumtions
B18: DRYWALL INT JAMBS | C18: NO | P18: Profile is trim profile, changes knife cost and set up fees
B19: FULL DRYWALL WRAP WINDOWS SLIDERS | C19: NO | P19: Drywall int jambs refers to places like barn doors, pocket doors, and wrapped openings
B20: SPECIES 1 | C20: Poplar | P20: Drwall wraped windows refers to the jambs on windows and sliding doors
B21: SPECIES 2 | P21: Up to 3 species can be selected to show on the final estimate
B22: SPECIES 3
B23: FINISH SIZE | C23: STANDARD | P23: Finish size will change the default sized of each piece of trim but can be overriden
P24: (See the chart on price data tab to see list of sizes)
A26: STYLE | B26: PART | C26: LF | D26: DESCRIPTION | E26: CUSTOM WIDTH | F26: CUSTOM THICKNESS | G26: STANDARD WIDTH | H26: STANDARD THICKNESS | I26: ECONOMY WIDTH | J26: ECONOMY THICKNESS | K26: UPGRADE WIDTH | L26: UPGRADED THICKNESS | M26: ACTUAL WIDTH | N26: ACTUAL THICKNESS
A27: CRAFTSMAN | B27: BASE | C27: =$C$7+$C$8*2 -> 350 | D27: =Table5[[#This Row],[STYLE]]&" "&Table5[[#This Row],[PART]] -> CRAFTSMAN BASE | G27: 5.25 | H27: 0.5 | I27: 2.25 | J27: 0.5 | K27: 7 | L27: 0.75 | M27: =IF(Table5[[#This Row],[CUSTOM WIDTH]]<>"",Table5[[#This Row],[CUSTOM WIDTH]],(IF($C$23="standard",Table5[[#This Row],[STANDARD WIDTH]],IF($C$23="economy",Table5[[#This Row],[ECONOMY WIDTH]],IF($C$23="upgraded",Table5[[#This Row],[UPGRADE WIDTH]],Table5[[#This Row],[CUSTOM WIDTH]]))))) -> 5.25 | N27: =IF(Table5[[#This Row],[CUSTOM THICKNESS]]<>"",Table5[[#This Row],[CUSTOM THICKNESS]],(IF($C$23="standard",Table5[[#This Row],[STANDARD THICKNESS]],IF($C$23="economy",Table5[[#This Row],[ECONOMY THICKNESS]],IF($C$23="upgraded",Table5[[#This Row],[UPGRADED THICKNESS]],Table5[[#This Row],[CUSTOM THICKNESS]]))))) -> 0.5 | P27: To override a default width select from the drop down on width
A28: CRAFTSMAN | B28: CASE | C28: =(2*$C$9*(ROUNDUP($C$15/12,0)))+(4*$C$12*(ROUNDUP($C$15/12,0)))+(IF($C$19="yes",0,(ROUNDUP($C$15/12,0))*2*($C$13+$C$14+$C$11))) -> 714 | D28: =Table5[[#This Row],[STYLE]]&" "&Table5[[#This Row],[PART]] -> CRAFTSMAN CASE | G28: 3.25 | H28: 0.625 | I28: 3.25 | J28: 0.625 | K28: 4.25 | L28: 1 | M28: =IF(Table5[[#This Row],[CUSTOM WIDTH]]<>"",Table5[[#This Row],[CUSTOM WIDTH]],(IF($C$23="standard",Table5[[#This Row],[STANDARD WIDTH]],IF($C$23="economy",Table5[[#This Row],[ECONOMY WIDTH]],IF($C$23="upgraded",Table5[[#This Row],[UPGRADE WIDTH]],Table5[[#This Row],[CUSTOM WIDTH]]))))) -> 3.25 | N28: =IF(Table5[[#This Row],[CUSTOM THICKNESS]]<>"",Table5[[#This Row],[CUSTOM THICKNESS]],(IF($C$23="standard",Table5[[#This Row],[STANDARD THICKNESS]],IF($C$23="economy",Table5[[#This Row],[ECONOMY THICKNESS]],IF($C$23="upgraded",Table5[[#This Row],[UPGRADED THICKNESS]],Table5[[#This Row],[CUSTOM THICKNESS]]))))) -> 0.625 | P28: To override a default on thickness enter any number between .5 and 2
A29: CRAFTSMAN | B29: HEADER | C29: =(ROUNDUP($C$15/12,0)/2)*($C$9+($C$12*2))+(IF(C19="yes",0,($C$10+$C$11+2*($C$13+$C$14)))) -> 139.5 | D29: =Table5[[#This Row],[STYLE]]&" "&Table5[[#This Row],[PART]] -> CRAFTSMAN HEADER | G29: 5.25 | H29: 0.875 | I29: 4.25 | J29: 0.75 | K29: 7 | L29: 1.125 | M29: =IF(Table5[[#This Row],[CUSTOM WIDTH]]<>"",Table5[[#This Row],[CUSTOM WIDTH]],(IF($C$23="standard",Table5[[#This Row],[STANDARD WIDTH]],IF($C$23="economy",Table5[[#This Row],[ECONOMY WIDTH]],IF($C$23="upgraded",Table5[[#This Row],[UPGRADE WIDTH]],Table5[[#This Row],[CUSTOM WIDTH]]))))) -> 5.25 | N29: =IF(Table5[[#This Row],[CUSTOM THICKNESS]]<>"",Table5[[#This Row],[CUSTOM THICKNESS]],(IF($C$23="standard",Table5[[#This Row],[STANDARD THICKNESS]],IF($C$23="economy",Table5[[#This Row],[ECONOMY THICKNESS]],IF($C$23="upgraded",Table5[[#This Row],[UPGRADED THICKNESS]],Table5[[#This Row],[CUSTOM THICKNESS]]))))) -> 0.875 | P29: Everything else in the lower table works from info provided in the take off table
A30: CRAFTSMAN | B30: INT JAMB | C30: =IF($C$18="yes",0,(ROUNDUP($C$15/12,0))*($C$13+$C$14)) -> 21 | D30: =Table5[[#This Row],[STYLE]]&" "&Table5[[#This Row],[PART]] -> CRAFTSMAN INT JAMB | G30: 4.75 | H30: 0.75 | I30: 4.75 | J30: 0.75 | K30: 4.75 | L30: 0.75 | M30: =IF(Table5[[#This Row],[CUSTOM WIDTH]]<>"",Table5[[#This Row],[CUSTOM WIDTH]],(IF($C$23="standard",Table5[[#This Row],[STANDARD WIDTH]],IF($C$23="economy",Table5[[#This Row],[ECONOMY WIDTH]],IF($C$23="upgraded",Table5[[#This Row],[UPGRADE WIDTH]],Table5[[#This Row],[CUSTOM WIDTH]]))))) -> 4.75 | N30: =IF(Table5[[#This Row],[CUSTOM THICKNESS]]<>"",Table5[[#This Row],[CUSTOM THICKNESS]],(IF($C$23="standard",Table5[[#This Row],[STANDARD THICKNESS]],IF($C$23="economy",Table5[[#This Row],[ECONOMY THICKNESS]],IF($C$23="upgraded",Table5[[#This Row],[UPGRADED THICKNESS]],Table5[[#This Row],[CUSTOM THICKNESS]]))))) -> 0.75
A31: CRAFTSMAN | B31: WINDOW JAMB | C31: =IF(C18="yes",0,((ROUNDUP(($C$15/12),0)*2)*$C$11+(ROUNDUP($C$15/12,0)*3)*$C$10)) -> 273 | D31: =Table5[[#This Row],[STYLE]]&" "&Table5[[#This Row],[PART]] -> CRAFTSMAN WINDOW JAMB | G31: 6 | H31: 0.75 | I31: 6 | J31: 0.75 | K31: 6 | L31: 0.75 | M31: =IF(Table5[[#This Row],[CUSTOM WIDTH]]<>"",Table5[[#This Row],[CUSTOM WIDTH]],(IF($C$23="standard",Table5[[#This Row],[STANDARD WIDTH]],IF($C$23="economy",Table5[[#This Row],[ECONOMY WIDTH]],IF($C$23="upgraded",Table5[[#This Row],[UPGRADE WIDTH]],Table5[[#This Row],[CUSTOM WIDTH]]))))) -> 6 | N31: =IF(Table5[[#This Row],[CUSTOM THICKNESS]]<>"",Table5[[#This Row],[CUSTOM THICKNESS]],(IF($C$23="standard",Table5[[#This Row],[STANDARD THICKNESS]],IF($C$23="economy",Table5[[#This Row],[ECONOMY THICKNESS]],IF($C$23="upgraded",Table5[[#This Row],[UPGRADED THICKNESS]],Table5[[#This Row],[CUSTOM THICKNESS]]))))) -> 0.75
A32: CRAFTSMAN | B32: SILL | C32: =C29 -> 139.5 | D32: =Table5[[#This Row],[STYLE]]&" "&Table5[[#This Row],[PART]] -> CRAFTSMAN SILL | G32: 7.25 | H32: 0.75 | I32: 7.25 | J32: 0.75 | K32: 7.25 | L32: 0.75 | M32: =IF(Table5[[#This Row],[CUSTOM WIDTH]]<>"",Table5[[#This Row],[CUSTOM WIDTH]],(IF($C$23="standard",Table5[[#This Row],[STANDARD WIDTH]],IF($C$23="economy",Table5[[#This Row],[ECONOMY WIDTH]],IF($C$23="upgraded",Table5[[#This Row],[UPGRADE WIDTH]],Table5[[#This Row],[CUSTOM WIDTH]]))))) -> 7.25 | N32: =IF(Table5[[#This Row],[CUSTOM THICKNESS]]<>"",Table5[[#This Row],[CUSTOM THICKNESS]],(IF($C$23="standard",Table5[[#This Row],[STANDARD THICKNESS]],IF($C$23="economy",Table5[[#This Row],[ECONOMY THICKNESS]],IF($C$23="upgraded",Table5[[#This Row],[UPGRADED THICKNESS]],Table5[[#This Row],[CUSTOM THICKNESS]]))))) -> 0.75
A33: CRAFTSMAN | B33: APRON | C33: =C32 -> 139.5 | D33: =Table5[[#This Row],[STYLE]]&" "&Table5[[#This Row],[PART]] -> CRAFTSMAN APRON | G33: =G27 -> 5.25 | H33: =H27 -> 0.5 | I33: =I27 -> 2.25 | J33: =J27 -> 0.5 | K33: =K27 -> 7 | L33: =L27 -> 0.75 | M33: =IF(Table5[[#This Row],[CUSTOM WIDTH]]<>"",Table5[[#This Row],[CUSTOM WIDTH]],(IF($C$23="standard",Table5[[#This Row],[STANDARD WIDTH]],IF($C$23="economy",Table5[[#This Row],[ECONOMY WIDTH]],IF($C$23="upgraded",Table5[[#This Row],[UPGRADE WIDTH]],Table5[[#This Row],[CUSTOM WIDTH]]))))) -> 5.25 | N33: =IF(Table5[[#This Row],[CUSTOM THICKNESS]]<>"",Table5[[#This Row],[CUSTOM THICKNESS]],(IF($C$23="standard",Table5[[#This Row],[STANDARD THICKNESS]],IF($C$23="economy",Table5[[#This Row],[ECONOMY THICKNESS]],IF($C$23="upgraded",Table5[[#This Row],[UPGRADED THICKNESS]],Table5[[#This Row],[CUSTOM THICKNESS]]))))) -> 0.5
A34: CRAFTSMAN PLUS | B34: DENTIL | C34: =C37*2 -> 279 | D34: =Table5[[#This Row],[STYLE]]&" "&Table5[[#This Row],[PART]] -> CRAFTSMAN PLUS DENTIL | G34: 1.5 | H34: 0.5 | I34: 0 | J34: 0 | K34: 2 | L34: 0.75 | M34: =IF(Table5[[#This Row],[CUSTOM WIDTH]]<>"",Table5[[#This Row],[CUSTOM WIDTH]],(IF($C$23="standard",Table5[[#This Row],[STANDARD WIDTH]],IF($C$23="economy",Table5[[#This Row],[ECONOMY WIDTH]],IF($C$23="upgraded",Table5[[#This Row],[UPGRADE WIDTH]],Table5[[#This Row],[CUSTOM WIDTH]]))))) -> 1.5 | N34: =IF(Table5[[#This Row],[CUSTOM THICKNESS]]<>"",Table5[[#This Row],[CUSTOM THICKNESS]],(IF($C$23="standard",Table5[[#This Row],[STANDARD THICKNESS]],IF($C$23="economy",Table5[[#This Row],[ECONOMY THICKNESS]],IF($C$23="upgraded",Table5[[#This Row],[UPGRADED THICKNESS]],Table5[[#This Row],[CUSTOM THICKNESS]]))))) -> 0.5
A35: CRAFTSMAN PLUS | B35: BASE | C35: =$C$7+$C$8*2 -> 350 | D35: =Table5[[#This Row],[STYLE]]&" "&Table5[[#This Row],[PART]] -> CRAFTSMAN PLUS BASE | G35: 5.25 | H35: 0.5 | I35: 2.25 | J35: 0.5 | K35: 7 | L35: 0.75 | M35: =IF(Table5[[#This Row],[CUSTOM WIDTH]]<>"",Table5[[#This Row],[CUSTOM WIDTH]],(IF($C$23="standard",Table5[[#This Row],[STANDARD WIDTH]],IF($C$23="economy",Table5[[#This Row],[ECONOMY WIDTH]],IF($C$23="upgraded",Table5[[#This Row],[UPGRADE WIDTH]],Table5[[#This Row],[CUSTOM WIDTH]]))))) -> 5.25 | N35: =IF(Table5[[#This Row],[CUSTOM THICKNESS]]<>"",Table5[[#This Row],[CUSTOM THICKNESS]],(IF($C$23="standard",Table5[[#This Row],[STANDARD THICKNESS]],IF($C$23="economy",Table5[[#This Row],[ECONOMY THICKNESS]],IF($C$23="upgraded",Table5[[#This Row],[UPGRADED THICKNESS]],Table5[[#This Row],[CUSTOM THICKNESS]]))))) -> 0.5
A36: CRAFTSMAN PLUS | B36: CASE | C36: =(2*$C$9*(ROUNDUP($C$15/12,0)))+(4*$C$12*(ROUNDUP($C$15/12,0)))+(IF($C$19="yes",0,(ROUNDUP($C$15/12,0))*(2*($C$13+$C$14+$C$11)))) -> 714 | D36: =Table5[[#This Row],[STYLE]]&" "&Table5[[#This Row],[PART]] -> CRAFTSMAN PLUS CASE | G36: 3.25 | H36: 0.625 | I36: 2.25 | J36: 0.625 | K36: 4.25 | L36: 1 | M36: =IF(Table5[[#This Row],[CUSTOM WIDTH]]<>"",Table5[[#This Row],[CUSTOM WIDTH]],(IF($C$23="standard",Table5[[#This Row],[STANDARD WIDTH]],IF($C$23="economy",Table5[[#This Row],[ECONOMY WIDTH]],IF($C$23="upgraded",Table5[[#This Row],[UPGRADE WIDTH]],Table5[[#This Row],[CUSTOM WIDTH]]))))) -> 3.25 | N36: =IF(Table5[[#This Row],[CUSTOM THICKNESS]]<>"",Table5[[#This Row],[CUSTOM THICKNESS]],(IF($C$23="standard",Table5[[#This Row],[STANDARD THICKNESS]],IF($C$23="economy",Table5[[#This Row],[ECONOMY THICKNESS]],IF($C$23="upgraded",Table5[[#This Row],[UPGRADED THICKNESS]],Table5[[#This Row],[CUSTOM THICKNESS]]))))) -> 0.625
A37: CRAFTSMAN PLUS | B37: HEADER | C37: =(ROUNDUP($C$15/12,0)/2)*($C$9+($C$12*2))+(IF(C32="yes",0,($C$10+$C$11+2*($C$13+$C$14)))) -> 139.5 | D37: =Table5[[#This Row],[STYLE]]&" "&Table5[[#This Row],[PART]] -> CRAFTSMAN PLUS HEADER | G37: 5.25 | H37: 0.875 | I37: 4.25 | J37: 0.75 | K37: 7 | L37: 1.125 | M37: =IF(Table5[[#This Row],[CUSTOM WIDTH]]<>"",Table5[[#This Row],[CUSTOM WIDTH]],(IF($C$23="standard",Table5[[#This Row],[STANDARD WIDTH]],IF($C$23="economy",Table5[[#This Row],[ECONOMY WIDTH]],IF($C$23="upgraded",Table5[[#This Row],[UPGRADE WIDTH]],Table5[[#This Row],[CUSTOM WIDTH]]))))) -> 5.25 | N37: =IF(Table5[[#This Row],[CUSTOM THICKNESS]]<>"",Table5[[#This Row],[CUSTOM THICKNESS]],(IF($C$23="standard",Table5[[#This Row],[STANDARD THICKNESS]],IF($C$23="economy",Table5[[#This Row],[ECONOMY THICKNESS]],IF($C$23="upgraded",Table5[[#This Row],[UPGRADED THICKNESS]],Table5[[#This Row],[CUSTOM THICKNESS]]))))) -> 0.875
A38: CRAFTSMAN PLUS | B38: INT JAMB | C38: =IF($C$18="yes",0,(ROUNDUP($C$15/12,0))*($C$13+$C$14)) -> 21 | D38: =Table5[[#This Row],[STYLE]]&" "&Table5[[#This Row],[PART]] -> CRAFTSMAN PLUS INT JAMB | G38: 4.75 | H38: 0.75 | I38: 4.75 | J38: 0.75 | K38: 4.75 | L38: 0.75 | M38: =IF(Table5[[#This Row],[CUSTOM WIDTH]]<>"",Table5[[#This Row],[CUSTOM WIDTH]],(IF($C$23="standard",Table5[[#This Row],[STANDARD WIDTH]],IF($C$23="economy",Table5[[#This Row],[ECONOMY WIDTH]],IF($C$23="upgraded",Table5[[#This Row],[UPGRADE WIDTH]],Table5[[#This Row],[CUSTOM WIDTH]]))))) -> 4.75 | N38: =IF(Table5[[#This Row],[CUSTOM THICKNESS]]<>"",Table5[[#This Row],[CUSTOM THICKNESS]],(IF($C$23="standard",Table5[[#This Row],[STANDARD THICKNESS]],IF($C$23="economy",Table5[[#This Row],[ECONOMY THICKNESS]],IF($C$23="upgraded",Table5[[#This Row],[UPGRADED THICKNESS]],Table5[[#This Row],[CUSTOM THICKNESS]]))))) -> 0.75
A39: CRAFTSMAN PLUS | B39: WINDOW JAMB | C39: =IF(C31="yes",0,((ROUNDUP(($C$15/12),0)*2)*$C$11+(ROUNDUP($C$15/12,0)*3)*$C$10)) -> 273 | D39: =Table5[[#This Row],[STYLE]]&" "&Table5[[#This Row],[PART]] -> CRAFTSMAN PLUS WINDOW JAMB | G39: 6 | H39: 0.75 | I39: 6 | J39: 0.75 | K39: 6 | L39: 0.75 | M39: =IF(Table5[[#This Row],[CUSTOM WIDTH]]<>"",Table5[[#This Row],[CUSTOM WIDTH]],(IF($C$23="standard",Table5[[#This Row],[STANDARD WIDTH]],IF($C$23="economy",Table5[[#This Row],[ECONOMY WIDTH]],IF($C$23="upgraded",Table5[[#This Row],[UPGRADE WIDTH]],Table5[[#This Row],[CUSTOM WIDTH]]))))) -> 6 | N39: =IF(Table5[[#This Row],[CUSTOM THICKNESS]]<>"",Table5[[#This Row],[CUSTOM THICKNESS]],(IF($C$23="standard",Table5[[#This Row],[STANDARD THICKNESS]],IF($C$23="economy",Table5[[#This Row],[ECONOMY THICKNESS]],IF($C$23="upgraded",Table5[[#This Row],[UPGRADED THICKNESS]],Table5[[#This Row],[CUSTOM THICKNESS]]))))) -> 0.75
A40: CRAFTSMAN PLUS | B40: SILL | C40: =C37 -> 139.5 | D40: =Table5[[#This Row],[STYLE]]&" "&Table5[[#This Row],[PART]] -> CRAFTSMAN PLUS SILL | G40: 7.25 | H40: 0.75 | I40: 7.25 | J40: 0.75 | K40: 7.25 | L40: 0.75 | M40: =IF(Table5[[#This Row],[CUSTOM WIDTH]]<>"",Table5[[#This Row],[CUSTOM WIDTH]],(IF($C$23="standard",Table5[[#This Row],[STANDARD WIDTH]],IF($C$23="economy",Table5[[#This Row],[ECONOMY WIDTH]],IF($C$23="upgraded",Table5[[#This Row],[UPGRADE WIDTH]],Table5[[#This Row],[CUSTOM WIDTH]]))))) -> 7.25 | N40: =IF(Table5[[#This Row],[CUSTOM THICKNESS]]<>"",Table5[[#This Row],[CUSTOM THICKNESS]],(IF($C$23="standard",Table5[[#This Row],[STANDARD THICKNESS]],IF($C$23="economy",Table5[[#This Row],[ECONOMY THICKNESS]],IF($C$23="upgraded",Table5[[#This Row],[UPGRADED THICKNESS]],Table5[[#This Row],[CUSTOM THICKNESS]]))))) -> 0.75
A41: CRAFTSMAN PLUS | B41: APRON | C41: =C37 -> 139.5 | D41: =Table5[[#This Row],[STYLE]]&" "&Table5[[#This Row],[PART]] -> CRAFTSMAN PLUS APRON | G41: =G35 -> 5.25 | H41: =H35 -> 0.5 | I41: =I35 -> 2.25 | J41: =J35 -> 0.5 | K41: =K35 -> 7 | L41: =L35 -> 0.75 | M41: =IF(Table5[[#This Row],[CUSTOM WIDTH]]<>"",Table5[[#This Row],[CUSTOM WIDTH]],(IF($C$23="standard",Table5[[#This Row],[STANDARD WIDTH]],IF($C$23="economy",Table5[[#This Row],[ECONOMY WIDTH]],IF($C$23="upgraded",Table5[[#This Row],[UPGRADE WIDTH]],Table5[[#This Row],[CUSTOM WIDTH]]))))) -> 5.25 | N41: =IF(Table5[[#This Row],[CUSTOM THICKNESS]]<>"",Table5[[#This Row],[CUSTOM THICKNESS]],(IF($C$23="standard",Table5[[#This Row],[STANDARD THICKNESS]],IF($C$23="economy",Table5[[#This Row],[ECONOMY THICKNESS]],IF($C$23="upgraded",Table5[[#This Row],[UPGRADED THICKNESS]],Table5[[#This Row],[CUSTOM THICKNESS]]))))) -> 0.5
A42: MITERED | B42: BASE | C42: =$C$7+$C$8*2 -> 350 | D42: =Table5[[#This Row],[STYLE]]&" "&Table5[[#This Row],[PART]] -> MITERED BASE | G42: 5.25 | H42: 0.5 | I42: 2.25 | J42: 0.5 | K42: 7 | L42: 0.75 | M42: =IF(Table5[[#This Row],[CUSTOM WIDTH]]<>"",Table5[[#This Row],[CUSTOM WIDTH]],(IF($C$23="standard",Table5[[#This Row],[STANDARD WIDTH]],IF($C$23="economy",Table5[[#This Row],[ECONOMY WIDTH]],IF($C$23="upgraded",Table5[[#This Row],[UPGRADE WIDTH]],Table5[[#This Row],[CUSTOM WIDTH]]))))) -> 5.25 | N42: =IF(Table5[[#This Row],[CUSTOM THICKNESS]]<>"",Table5[[#This Row],[CUSTOM THICKNESS]],(IF($C$23="standard",Table5[[#This Row],[STANDARD THICKNESS]],IF($C$23="economy",Table5[[#This Row],[ECONOMY THICKNESS]],IF($C$23="upgraded",Table5[[#This Row],[UPGRADED THICKNESS]],Table5[[#This Row],[CUSTOM THICKNESS]]))))) -> 0.5
A43: MITERED | B43: CASE | C43: =(2*$C$9*(ROUNDUP($C$15/12,0)))+(4*$C$12*(ROUNDUP($C$15/12,0)))+(IF($C$19="yes",0,(ROUNDUP($C$15/12,0)*2)*(2*($C$13+$C$14+$C$11)))) -> 966 | D43: =Table5[[#This Row],[STYLE]]&" "&Table5[[#This Row],[PART]] -> MITERED CASE | G43: 3.25 | H43: 0.625 | I43: 2.25 | J43: 0.625 | K43: 4.25 | L43: 1 | M43: =IF(Table5[[#This Row],[CUSTOM WIDTH]]<>"",Table5[[#This Row],[CUSTOM WIDTH]],(IF($C$23="standard",Table5[[#This Row],[STANDARD WIDTH]],IF($C$23="economy",Table5[[#This Row],[ECONOMY WIDTH]],IF($C$23="upgraded",Table5[[#This Row],[UPGRADE WIDTH]],Table5[[#This Row],[CUSTOM WIDTH]]))))) -> 3.25 | N43: =IF(Table5[[#This Row],[CUSTOM THICKNESS]]<>"",Table5[[#This Row],[CUSTOM THICKNESS]],(IF($C$23="standard",Table5[[#This Row],[STANDARD THICKNESS]],IF($C$23="economy",Table5[[#This Row],[ECONOMY THICKNESS]],IF($C$23="upgraded",Table5[[#This Row],[UPGRADED THICKNESS]],Table5[[#This Row],[CUSTOM THICKNESS]]))))) -> 0.625
...

Sheet Door Schedule
A2: Line Number | B2: Type | C2: Width | D2: Height | E2: LH | F2: RH | G2: Total | H2: Width Name | I2: Height Name | J2: Door Name | K2: Door Price | L2: Finish Price | N2: We probably need to get a quote for each schedule/option that isn't on the standard price sheets, then plug them in by hand
A3: 1 | B3: =IFERROR(INDEX(Table18[Type],MATCH(Table17[[#This Row],[Line Number]],Table18[Line Number],0)),"") -> Swing | C3: =IFERROR(INDEX(Table18[Width],MATCH(Table17[[#This Row],[Line Number]],Table18[Line Number],0)),"") -> 26 | D3: =IFERROR(INDEX(Table18[Height],MATCH(Table17[[#This Row],[Line Number]],Table18[Line Number],0)),"") -> 80 | E3: =IFERROR(INDEX(Table18[LH],MATCH(Table17[[#This Row],[Line Number]],Table18[Line Number],0)),"") -> 1 | F3: =IFERROR(INDEX(Table18[RH],MATCH(Table17[[#This Row],[Line Number]],Table18[Line Number],0)),"") -> 0 | G3: =IFERROR(Table17[[#This Row],[RH]]+Table17[[#This Row],[LH]],"") -> 1 | H3: =IFERROR(INDEX(Table16[Name],MATCH(Table17[[#This Row],[Width]],Table16[Size],0)),"") -> 2' 2" | I3: =IFERROR(INDEX(Table16[Name],MATCH(Table17[[#This Row],[Height]],Table16[Size],0)),"") -> 6' 8" | J3: =IF(Table17[[#This Row],[Type]]="","",Table17[[#This Row],[Width Name]]&"/"&Table17[[#This Row],[Height Name]]&" "&Table17[[#This Row],[Type]]) -> 2' 2"/6' 8" Swing | N3: You can request a quote by coping and pasting the results in the door estimate tab then emailing Paul at Rugby
A4: 2 | B4: =IFERROR(INDEX(Table18[Type],MATCH(Table17[[#This Row],[Line Number]],Table18[Line Number],0)),"") -> Swing | C4: =IFERROR(INDEX(Table18[Width],MATCH(Table17[[#This Row],[Line Number]],Table18[Line Number],0)),"") -> 28 | D4: =IFERROR(INDEX(Table18[Height],MATCH(Table17[[#This Row],[Line Number]],Table18[Line Number],0)),"") -> 80 | E4: =IFERROR(INDEX(Table18[LH],MATCH(Table17[[#This Row],[Line Number]],Table18[Line Number],0)),"") -> 0 | F4: =IFERROR(INDEX(Table18[RH],MATCH(Table17[[#This Row],[Line Number]],Table18[Line Number],0)),"") -> 2 | G4: =IFERROR(Table17[[#This Row],[RH]]+Table17[[#This Row],[LH]],"") -> 2 | H4: =IFERROR(INDEX(Table16[Name],MATCH(Table17[[#This Row],[Width]],Table16[Size],0)),"") -> 2' 4" | I4: =IFERROR(INDEX(Table16[Name],MATCH(Table17[[#This Row],[Height]],Table16[Size],0)),"") -> 6' 8" | J4: =IF(Table17[[#This Row],[Type]]="","",Table17[[#This Row],[Width Name]]&"/"&Table17[[#This Row],[Height Name]]&" "&Table17[[#This Row],[Type]]) -> 2' 4"/6' 8" Swing
A5: 3 | B5: =IFERROR(INDEX(Table18[Type],MATCH(Table17[[#This Row],[Line Number]],Table18[Line Number],0)),"") -> Swing | C5: =IFERROR(INDEX(Table18[Width],MATCH(Table17[[#This Row],[Line Number]],Table18[Line Number],0)),"") -> 30 | D5: =IFERROR(INDEX(Table18[Height],MATCH(Table17[[#This Row],[Line Number]],Table18[Line Number],0)),"") -> 84 | E5: =IFERROR(INDEX(Table18[LH],MATCH(Table17[[#This Row],[Line Number]],Table18[Line Number],0)),"") -> 3 | F5: =IFERROR(INDEX(Table18[RH],MATCH(Table17[[#This Row],[Line Number]],Table18[Line Number],0)),"") -> 0 | G5: =IFERROR(Table17[[#This Row],[RH]]+Table17[[#This Row],[LH]],"") -> 3 | H5: =IFERROR(INDEX(Table16[Name],MATCH(Table17[[#This Row],[Width]],Table16[Size],0)),"") -> 2' 6" | I5: =IFERROR(INDEX(Table16[Name],MATCH(Table17[[#This Row],[Height]],Table16[Size],0)),"") -> 7' 0" | J5: =IF(Table17[[#This Row],[Type]]="","",Table17[[#This Row],[Width Name]]&"/"&Table17[[#This Row],[Height Name]]&" "&Table17[[#This Row],[Type]]) -> 2' 6"/7' 0" Swing
A6: 4 | B6: =IFERROR(INDEX(Table18[Type],MATCH(Table17[[#This Row],[Line Number]],Table18[Line Number],0)),"") -> Swing | C6: =IFERROR(INDEX(Table18[Width],MATCH(Table17[[#This Row],[Line Number]],Table18[Line Number],0)),"") -> 32 | D6: =IFERROR(INDEX(Table18[Height],MATCH(Table17[[#This Row],[Line Number]],Table18[Line Number],0)),"") -> 84 | E6: =IFERROR(INDEX(Table18[LH],MATCH(Table17[[#This Row],[Line Number]],Table18[Line Number],0)),"") -> 2 | F6: =IFERROR(INDEX(Table18[RH],MATCH(Table17[[#This Row],[Line Number]],Table18[Line Number],0)),"") -> 0 | G6: =IFERROR(Table17[[#This Row],[RH]]+Table17[[#This Row],[LH]],"") -> 2 | H6: =IFERROR(INDEX(Table16[Name],MATCH(Table17[[#This Row],[Width]],Table16[Size],0)),"") -> 2' 8" | I6: =IFERROR(INDEX(Table16[Name],MATCH(Table17[[#This Row],[Height]],Table16[Size],0)),"") -> 7' 0" | J6: =IF(Table17[[#This Row],[Type]]="","",Table17[[#This Row],[Width Name]]&"/"&Table17[[#This Row],[Height Name]]&" "&Table17[[#This Row],[Type]]) -> 2' 8"/7' 0" Swing
A7: 5 | B7: =IFERROR(INDEX(Table18[Type],MATCH(Table17[[#This Row],[Line Number]],Table18[Line Number],0)),"") -> Swing | C7: =IFERROR(INDEX(Table18[Width],MATCH(Table17[[#This Row],[Line Number]],Table18[Line Number],0)),"") -> 36 | D7: =IFERROR(INDEX(Table18[Height],MATCH(Table17[[#This Row],[Line Number]],Table18[Line Number],0)),"") -> 96 | E7: =IFERROR(INDEX(Table18[LH],MATCH(Table17[[#This Row],[Line Number]],Table18[Line Number],0)),"") -> 0 | F7: =IFERROR(INDEX(Table18[RH],MATCH(Table17[[#This Row],[Line Number]],Table18[Line Number],0)),"") -> 1 | G7: =IFERROR(Table17[[#This Row],[RH]]+Table17[[#This Row],[LH]],"") -> 1 | H7: =IFERROR(INDEX(Table16[Name],MATCH(Table17[[#This Row],[Width]],Table16[Size],0)),"") -> 3' 0" | I7: =IFERROR(INDEX(Table16[Name],MATCH(Table17[[#This Row],[Height]],Table16[Size],0)),"") -> 8' 0" | J7: =IF(Table17[[#This Row],[Type]]="","",Table17[[#This Row],[Width Name]]&"/"&Table17[[#This Row],[Height Name]]&" "&Table17[[#This Row],[Type]]) -> 3' 0"/8' 0" Swing
A8: 6 | B8: =IFERROR(INDEX(Table18[Type],MATCH(Table17[[#This Row],[Line Number]],Table18[Line Number],0)),"") | C8: =IFERROR(INDEX(Table18[Width],MATCH(Table17[[#This Row],[Line Number]],Table18[Line Number],0)),"") | D8: =IFERROR(INDEX(Table18[Height],MATCH(Table17[[#This Row],[Line Number]],Table18[Line Number],0)),"") | E8: =IFERROR(INDEX(Table18[LH],MATCH(Table17[[#This Row],[Line Number]],Table18[Line Number],0)),"") | F8: =IFERROR(INDEX(Table18[RH],MATCH(Table17[[#This Row],[Line Number]],Table18[Line Number],0)),"") | G8: =IFERROR(Table17[[#This Row],[RH]]+Table17[[#This Row],[LH]],"") | H8: =IFERROR(INDEX(Table16[Name],MATCH(Table17[[#This Row],[Width]],Table16[Size],0)),"") | I8: =IFERROR(INDEX(Table16[Name],MATCH(Table17[[#This Row],[Height]],Table16[Size],0)),"") | J8: =IF(Table17[[#This Row],[Type]]="","",Table17[[#This Row],[Width Name]]&"/"&Table17[[#This Row],[Height Name]]&" "&Table17[[#This Row],[Type]])
A9: 7 | B9: =IFERROR(INDEX(Table18[Type],MATCH(Table17[[#This Row],[Line Number]],Table18[Line Number],0)),"") | C9: =IFERROR(INDEX(Table18[Width],MATCH(Table17[[#This Row],[Line Number]],Table18[Line Number],0)),"") | D9: =IFERROR(INDEX(Table18[Height],MATCH(Table17[[#This Row],[Line Number]],Table18[Line Number],0)),"") | E9: =IFERROR(INDEX(Table18[LH],MATCH(Table17[[#This Row],[Line Number]],Table18[Line Number],0)),"") | F9: =IFERROR(INDEX(Table18[RH],MATCH(Table17[[#This Row],[Line Number]],Table18[Line Number],0)),"") | G9: =IFERROR(Table17[[#This Row],[RH]]+Table17[[#This Row],[LH]],"") | H9: =IFERROR(INDEX(Table16[Name],MATCH(Table17[[#This Row],[Width]],Table16[Size],0)),"") | I9: =IFERROR(INDEX(Table16[Name],MATCH(Table17[[#This Row],[Height]],Table16[Size],0)),"") | J9: =IF(Table17[[#This Row],[Type]]="","",Table17[[#This Row],[Width Name]]&"/"&Table17[[#This Row],[Height Name]]&" "&Table17[[#This Row],[Type]])
A10: 8 | B10: =IFERROR(INDEX(Table18[Type],MATCH(Table17[[#This Row],[Line Number]],Table18[Line Number],0)),"") | C10: =IFERROR(INDEX(Table18[Width],MATCH(Table17[[#This Row],[Line Number]],Table18[Line Number],0)),"") | D10: =IFERROR(INDEX(Table18[Height],MATCH(Table17[[#This Row],[Line Number]],Table18[Line Number],0)),"") | E10: =IFERROR(INDEX(Table18[LH],MATCH(Table17[[#This Row],[Line Number]],Table18[Line Number],0)),"") | F10: =IFERROR(INDEX(Table18[RH],MATCH(Table17[[#This Row],[Line Number]],Table18[Line Number],0)),"") | G10: =IFERROR(Table17[[#This Row],[RH]]+Table17[[#This Row],[LH]],"") | H10: =IFERROR(INDEX(Table16[Name],MATCH(Table17[[#This Row],[Width]],Table16[Size],0)),"") | I10: =IFERROR(INDEX(Table16[Name],MATCH(Table17[[#This Row],[Height]],Table16[Size],0)),"") | J10: =IF(Table17[[#This Row],[Type]]="","",Table17[[#This Row],[Width Name]]&"/"&Table17[[#This Row],[Height Name]]&" "&Table17[[#This Row],[Type]])
A11: 9 | B11: =IFERROR(INDEX(Table18[Type],MATCH(Table17[[#This Row],[Line Number]],Table18[Line Number],0)),"") | C11: =IFERROR(INDEX(Table18[Width],MATCH(Table17[[#This Row],[Line Number]],Table18[Line Number],0)),"") | D11: =IFERROR(INDEX(Table18[Height],MATCH(Table17[[#This Row],[Line Number]],Table18[Line Number],0)),"") | E11: =IFERROR(INDEX(Table18[LH],MATCH(Table17[[#This Row],[Line Number]],Table18[Line Number],0)),"") | F11: =IFERROR(INDEX(Table18[RH],MATCH(Table17[[#This Row],[Line Number]],Table18[Line Number],0)),"") | G11: =IFERROR(Table17[[#This Row],[RH]]+Table17[[#This Row],[LH]],"") | H11: =IFERROR(INDEX(Table16[Name],MATCH(Table17[[#This Row],[Width]],Table16[Size],0)),"") | I11: =IFERROR(INDEX(Table16[Name],MATCH(Table17[[#This Row],[Height]],Table16[Size],0)),"") | J11: =IF(Table17[[#This Row],[Type]]="","",Table17[[#This Row],[Width Name]]&"/"&Table17[[#This Row],[Height Name]]&" "&Table17[[#This Row],[Type]])
A12: 10 | B12: =IFERROR(INDEX(Table18[Type],MATCH(Table17[[#This Row],[Line Number]],Table18[Line Number],0)),"") | C12: =IFERROR(INDEX(Table18[Width],MATCH(Table17[[#This Row],[Line Number]],Table18[Line Number],0)),"") | D12: =IFERROR(INDEX(Table18[Height],MATCH(Table17[[#This Row],[Line Number]],Table18[Line Number],0)),"") | E12: =IFERROR(INDEX(Table18[LH],MATCH(Table17[[#This Row],[Line Number]],Table18[Line Number],0)),"") | F12: =IFERROR(INDEX(Table18[RH],MATCH(Table17[[#This Row],[Line Number]],Table18[Line Number],0)),"") | G12: =IFERROR(Table17[[#This Row],[RH]]+Table17[[#This Row],[LH]],"") | H12: =IFERROR(INDEX(Table16[Name],MATCH(Table17[[#This Row],[Width]],Table16[Size],0)),"") | I12: =IFERROR(INDEX(Table16[Name],MATCH(Table17[[#This Row],[Height]],Table16[Size],0)),"") | J12: =IF(Table17[[#This Row],[Type]]="","",Table17[[#This Row],[Width Name]]&"/"&Table17[[#This Row],[Height Name]]&" "&Table17[[#This Row],[Type]])
A13: 11 | B13: =IFERROR(INDEX(Table18[Type],MATCH(Table17[[#This Row],[Line Number]],Table18[Line Number],0)),"") | C13: =IFERROR(INDEX(Table18[Width],MATCH(Table17[[#This Row],[Line Number]],Table18[Line Number],0)),"") | D13: =IFERROR(INDEX(Table18[Height],MATCH(Table17[[#This Row],[Line Number]],Table18[Line Number],0)),"") | E13: =IFERROR(INDEX(Table18[LH],MATCH(Table17[[#This Row],[Line Number]],Table18[Line Number],0)),"") | F13: =IFERROR(INDEX(Table18[RH],MATCH(Table17[[#This Row],[Line Number]],Table18[Line Number],0)),"") | G13: =IFERROR(Table17[[#This Row],[RH]]+Table17[[#This Row],[LH]],"") | H13: =IFERROR(INDEX(Table16[Name],MATCH(Table17[[#This Row],[Width]],Table16[Size],0)),"") | I13: =IFERROR(INDEX(Table16[Name],MATCH(Table17[[#This Row],[Height]],Table16[Size],0)),"") | J13: =IF(Table17[[#This Row],[Type]]="","",Table17[[#This Row],[Width Name]]&"/"&Table17[[#This Row],[Height Name]]&" "&Table17[[#This Row],[Type]])
A14: 12 | B14: =IFERROR(INDEX(Table18[Type],MATCH(Table17[[#This Row],[Line Number]],Table18[Line Number],0)),"") | C14: =IFERROR(INDEX(Table18[Width],MATCH(Table17[[#This Row],[Line Number]],Table18[Line Number],0)),"") | D14: =IFERROR(INDEX(Table18[Height],MATCH(Table17[[#This Row],[Line Number]],Table18[Line Number],0)),"") | E14: =IFERROR(INDEX(Table18[LH],MATCH(Table17[[#This Row],[Line Number]],Table18[Line Number],0)),"") | F14: =IFERROR(INDEX(Table18[RH],MATCH(Table17[[#This Row],[Line Number]],Table18[Line Number],0)),"") | G14: =IFERROR(Table17[[#This Row],[RH]]+Table17[[#This Row],[LH]],"") | H14: =IFERROR(INDEX(Table16[Name],MATCH(Table17[[#This Row],[Width]],Table16[Size],0)),"") | I14: =IFERROR(INDEX(Table16[Name],MATCH(Table17[[#This Row],[Height]],Table16[Size],0)),"") | J14: =IF(Table17[[#This Row],[Type]]="","",Table17[[#This Row],[Width Name]]&"/"&Table17[[#This Row],[Height Name]]&" "&Table17[[#This Row],[Type]])
A15: 13 | B15: =IFERROR(INDEX(Table18[Type],MATCH(Table17[[#This Row],[Line Number]],Table18[Line Number],0)),"") | C15: =IFERROR(INDEX(Table18[Width],MATCH(Table17[[#This Row],[Line Number]],Table18[Line Number],0)),"") | D15: =IFERROR(INDEX(Table18[Height],MATCH(Table17[[#This Row],[Line Number]],Table18[Line Number],0)),"") | E15: =IFERROR(INDEX(Table18[LH],MATCH(Table17[[#This Row],[Line Number]],Table18[Line Number],0)),"") | F15: =IFERROR(INDEX(Table18[RH],MATCH(Table17[[#This Row],[Line Number]],Table18[Line Number],0)),"") | G15: =IFERROR(Table17[[#This Row],[RH]]+Table17[[#This Row],[LH]],"") | H15: =IFERROR(INDEX(Table16[Name],MATCH(Table17[[#This Row],[Width]],Table16[Size],0)),"") | I15: =IFERROR(INDEX(Table16[Name],MATCH(Table17[[#This Row],[Height]],Table16[Size],0)),"") | J15: =IF(Table17[[#This Row],[Type]]="","",Table17[[#This Row],[Width Name]]&"/"&Table17[[#This Row],[Height Name]]&" "&Table17[[#This Row],[Type]])
... A52: 50 | B52: =IFERROR(INDEX(Table18[Type],MATCH(Table17[[#This Row],[Line Number]],Table18[Line Number],0)),"") | C52: =IFERROR(INDEX(Table18[Width],MATCH(Table17[[#This Row],[Line Number]],Table18[Line Number],0)),"") | D52: =IFERROR(INDEX(Table18[Height],MATCH(Table17[[#This Row],[Line Number]],Table18[Line Number],0)),"") | E52: =IFERROR(INDEX(Table18[LH],MATCH(Table17[[#This Row],[Line Number]],Table18[Line Number],0)),"") | F52: =IFERROR(INDEX(Table18[RH],MATCH(Table17[[#This Row],[Line Number]],Table18[Line Number],0)),"") | G52: =IFERROR(Table17[[#This Row],[RH]]+Table17[[#This Row],[LH]],"") | H52: =IFERROR(INDEX(Table16[Name],MATCH(Table17[[#This Row],[Width]],Table16[Size],0)),"") | I52: =IFERROR(INDEX(Table16[Name],MATCH(Table17[[#This Row],[Height]],Table16[Size],0)),"") | J52: =IF(Table17[[#This Row],[Type]]="","",Table17[[#This Row],[Width Name]]&"/"&Table17[[#This Row],[Height Name]]&" "&Table17[[#This Row],[Type]])

Sheet Door Price Data
B2: Size | C2: Moulded 4-9/16 fjp | D2: Melrose Berkley 4-9/16 FJP | E2: Logan * Lincoln 4-9/16 FJP | F2: Winslow 4-9/16 FJP | G2: Birch 4-9/16 FJP | H2: Oak 4-9/16 FJP | I2: PCHB 4-9/16 FJP | K2: SLAB ONLY DEDUCT 60 ON 6/8 AND 85 ON 8/0
B3: 1-6 6-8 1-3/8 HC | C3: 108.3 | D3: 123.1 | E3: 122 | F3: 118.65 | G3: 124.1 | H3: 127.9 | I3: 90.6
B4: 1-8 6-8 1-3/8 HC | C4: 108.3 | D4: 123.1 | E4: 122 | F4: 118.65 | G4: 124.1 | H4: 127.9 | I4: 90.6
B5: 1-10 6-8 1-3/8 HC | C5: 108.3 | D5: 123.1 | E5: 122 | F5: 118.65 | G5: 124.1 | H5: 127.9 | I5: 90.6
B6: 2-0 6-8 1-3/8 HC | C6: 108.3 | D6: 123.1 | E6: 122 | F6: 118.65 | G6: 125 | H6: 127.9 | I6: 90.6
B7: 2-2 6-8 1-3/8 HC | C7: 111.9 | D7: 126.3 | E7: 122.75 | F7: 122.2 | G7: 131.25 | H7: 130.5 | I7: 93.1
B8: 2-4 6-8 1-3/8 HC | C8: 111.9 | D8: 126.3 | E8: 122.75 | F8: 122.2 | G8: 131.25 | H8: 136.3 | I8: 93.1
B9: 2-6 6-8 1-3/8 HC | C9: 111.9 | D9: 129.75 | E9: 125.25 | F9: 124.6 | G9: 131.25 | H9: 136.3 | I9: 94.35
B10: 2-8 6-8 1-3/8 HC | C10: 117.35 | D10: 133.3 | E10: 127.9 | F10: 127.26 | G10: 134.75 | H10: 139.05 | I10: 96.3
B11: 2-10 6-8 1-3/8 HC | C11: 122.25 | D11: 139.45 | E11: 132.5 | F11: 132.4 | G11: 139 | H11: 139 | I11: 98.45
B12: 3-0 6-8 1-3/8 HC | C12: 122.25 | D12: 139.45 | E12: 132.5 | F12: 132.4 | G12: 139 | H12: 144.6 | I12: 98.45
B13: 1-6 6-8 1-3/8 SC | C13: 143.46 | E13: 154.72
B14: 2-0 6-8 1-3/8 SC | C14: 143.46 | D14: 164.9 | E14: 154.72 | F14: 153.95 | G14: 134.1 | H14: 142.2 | I14: 120.8
B15: 2-4 6-8 1-3/8 SC | C15: 148.6 | D15: 171.4 | E15: 158.85 | F15: 157.2 | G15: 142.8 | H15: 151.2 | I15: 122.5
B16: 2-6 6-8 1-3/8 SC | C16: 148.9 | D16: 171.65 | E16: 158.85 | F16: 157.46 | G16: 149.4 | H16: 158 | I16: 124.1
B17: 2-8 6-8 1-3/8 SC | C17: 154.35 | D17: 178.3 | E17: 164.1 | F17: 163.24 | G17: 151.95 | H17: 160.55 | I17: 129.95
B18: 3-0 6-8 1-3/8 SC | C18: 158.15 | D18: 183.45 | E18: 168.1 | F18: 167.17 | G18: 159.1 | H18: 168.7 | I18: 131.1
B19: 2-6 6-8 1-3/4 20 Stmp | G19: 249.8 | H19: 252.4 | I19: 215.2
B20: 2-8 6-8 1-3/4 20 Stmp | C20: 251.5 | D20: 262.5 | E20: 268.6 | F20: 263.8 | G20: 254.8 | H20: 285.1 | I20: 221.6
B21: 3-0 6-8 1-3/4 20 Stmp | C21: 255.4 | D21: 266.7 | E21: 272.5 | F21: 267.7 | G21: 262.65 | H21: 266.85 | I21: 226.2
B22: 2-0 8-0 1-3/8 HC | C22: 179.3 | E22: 200.75
B23: 2-4 8-0 1-3/8 HC | C23: 185.5 | E23: 208.1
B24: 2-6 8-0 1-3/8 HC | C24: 189.5 | E24: 208.1
B25: 2-8 8-0 1-3/8 HC | C25: 192.65 | E25: 215.76
B26: 3-0 8-0 1-3/8 HC | C26: 199.75 | E26: 225.1
B27: 2-0 8-0 1-3/8 SC | C27: 224.25 | E27: 260.6 | G27: 239 | I27: 182.8
B28: 2-4 8-0 1-3/8 SC | C28: 231.1 | E28: 268.75 | G28: 250.8 | I28: 186.4
B29: 2-6 8-0 1-3/8 SC | C29: 238.8 | E29: 268.75 | G29: 250.8 | I29: 190.6
B30: 2-8 8-0 1-3/8 SC | C30: 238.8 | E30: 276.4 | G30: 255.25 | I30: 191.3
B31: 3-0 8-0 1-3/8 SC | C31: 246.6 | E31: 281.8 | G31: 264.45 | I31: 196.75
B32: 2-8 8-0 1-3/4 20 Stmp | C32: 335 | E32: 430.4
B33: 3-0 8-0 1-3/4 20 Stmp | C33: 389 | E33: 436.3 | G33: 401.25 | I33: 341.4

Sheet Door Take Off
B2: =COUNT(Table11[Line Number]) -> 2 | C2: 80" | I2: =COUNT(Table11[Line Number]) -> 2 | J2: 84" | P2: =COUNT(Table11[Line Number]) -> 2 | Q2: 96"
B3: Line Number | C3: Type | D3: Width | E3: LH | F3: RH | G3: Total | I3: Line Number | J3: Type | K3: Width | L3: LH | M3: RH | N3: Total | P3: Line Number | Q3: Type | R3: Width | S3: LH | T3: RH | U3: Total | W3: Filter out door types and sizes not in use to make filling out the table easier | Y3: Size | Z3: Name | AB3: Line Number | AC3: Type | AD3: Width | AE3: Height | AF3: LH | AG3: RH | AH3: total
B4: =IF(Table11[[#This Row],[Total]]=0,"",(MAX(B$3:B3)+1)) | C4: Swing | D4: 24 | G4: =Table11[[#This Row],[RH]]+Table11[[#This Row],[LH]] -> 0 | I4: =IF(Table1115[[#This Row],[Total]]=0,"",(MAX(I$3:I3)+1)+(MAX(Table11[Line Number]))) | J4: Swing | K4: 24 | N4: =Table1115[[#This Row],[RH]]+Table1115[[#This Row],[LH]] -> 0 | P4: =IF(Table1116[[#This Row],[Total]]=0,"",(MAX(P$3:P3)+1)+MAX(Table1115[Line Number])) | Q4: Swing | R4: 24 | U4: =Table1116[[#This Row],[RH]]+Table1116[[#This Row],[LH]] -> 0 | W4: Note each door height has its own table | Y4: 24 | Z4: =INT(Y4/12)&"' "&MOD(Y4,12)&"""" -> 2' 0" | AB4: =IF(Table18[[#This Row],[total]]=0,"",(MAX($AB$3:$AB3)+1)) | AC4: Swing | AD4: 24 | AE4: 80 | AF4: =Table11[[#This Row],[LH]] -> 0 | AG4: =Table11[[#This Row],[RH]] -> 0 | AH4: =Table18[[#This Row],[RH]]+Table18[[#This Row],[LH]] -> 0
B5: =IF(Table11[[#This Row],[Total]]=0,"",(MAX(B$3:B4)+1)) -> 1 | C5: Swing | D5: 26 | E5: 1 | G5: =Table11[[#This Row],[RH]]+Table11[[#This Row],[LH]] -> 1 | I5: =IF(Table1115[[#This Row],[Total]]=0,"",(MAX(I$3:I4)+1)+(MAX(Table11[Line Number]))) | J5: Swing | K5: 26 | N5: =Table1115[[#This Row],[RH]]+Table1115[[#This Row],[LH]] -> 0 | P5: =IF(Table1116[[#This Row],[Total]]=0,"",(MAX(P$3:P4)+1)+MAX(Table1115[Line Number])) | Q5: Swing | R5: 26 | U5: =Table1116[[#This Row],[RH]]+Table1116[[#This Row],[LH]] -> 0 | W5: Enter the number of LH in swing or RH in swing according to plans | Y5: 26 | Z5: =INT(Y5/12)&"' "&MOD(Y5,12)&"""" -> 2' 2" | AB5: =IF(Table18[[#This Row],[total]]=0,"",(MAX($AB$3:$AB4)+1)) -> 1 | AC5: Swing | AD5: 26 | AE5: 80 | AF5: =Table11[[#This Row],[LH]] -> 1 | AG5: =Table11[[#This Row],[RH]] -> 0 | AH5: =Table18[[#This Row],[RH]]+Table18[[#This Row],[LH]] -> 1
B6: =IF(Table11[[#This Row],[Total]]=0,"",(MAX(B$3:B5)+1)) -> 2 | C6: Swing | D6: 28 | F6: 2 | G6: =Table11[[#This Row],[RH]]+Table11[[#This Row],[LH]] -> 2 | I6: =IF(Table1115[[#This Row],[Total]]=0,"",(MAX(I$3:I5)+1)+(MAX(Table11[Line Number]))) | J6: Swing | K6: 28 | N6: =Table1115[[#This Row],[RH]]+Table1115[[#This Row],[LH]] -> 0 | P6: =IF(Table1116[[#This Row],[Total]]=0,"",(MAX(P$3:P5)+1)+MAX(Table1115[Line Number])) | Q6: Swing | R6: 28 | U6: =Table1116[[#This Row],[RH]]+Table1116[[#This Row],[LH]] -> 0 | Y6: 28 | Z6: =INT(Y6/12)&"' "&MOD(Y6,12)&"""" -> 2' 4" | AB6: =IF(Table18[[#This Row],[total]]=0,"",(MAX($AB$3:$AB5)+1)) -> 2 | AC6: Swing | AD6: 28 | AE6: 80 | AF6: =Table11[[#This Row],[LH]] -> 0 | AG6: =Table11[[#This Row],[RH]] -> 2 | AH6: =Table18[[#This Row],[RH]]+Table18[[#This Row],[LH]] -> 2
B7: =IF(Table11[[#This Row],[Total]]=0,"",(MAX(B$3:B6)+1)) | C7: Swing | D7: 30 | G7: =Table11[[#This Row],[RH]]+Table11[[#This Row],[LH]] -> 0 | I7: =IF(Table1115[[#This Row],[Total]]=0,"",(MAX(I$3:I6)+1)+(MAX(Table11[Line Number]))) -> 3 | J7: Swing | K7: 30 | L7: 3 | N7: =Table1115[[#This Row],[RH]]+Table1115[[#This Row],[LH]] -> 3 | P7: =IF(Table1116[[#This Row],[Total]]=0,"",(MAX(P$3:P6)+1)+MAX(Table1115[Line Number])) | Q7: Swing | R7: 30 | U7: =Table1116[[#This Row],[RH]]+Table1116[[#This Row],[LH]] -> 0 | Y7: 30 | Z7: =INT(Y7/12)&"' "&MOD(Y7,12)&"""" -> 2' 6" | AB7: =IF(Table18[[#This Row],[total]]=0,"",(MAX($AB$3:$AB6)+1)) | AC7: Swing | AD7: 30 | AE7: 80 | AF7: =Table11[[#This Row],[LH]] -> 0 | AG7: =Table11[[#This Row],[RH]] -> 0 | AH7: =Table18[[#This Row],[RH]]+Table18[[#This Row],[LH]] -> 0
B8: =IF(Table11[[#This Row],[Total]]=0,"",(MAX(B$3:B7)+1)) | C8: Swing | D8: 32 | G8: =Table11[[#This Row],[RH]]+Table11[[#This Row],[LH]] -> 0 | I8: =IF(Table1115[[#This Row],[Total]]=0,"",(MAX(I$3:I7)+1)+(MAX(Table11[Line Number]))) -> 6 | J8: Swing | K8: 32 | L8: 2 | N8: =Table1115[[#This Row],[RH]]+Table1115[[#This Row],[LH]] -> 2 | P8: =IF(Table1116[[#This Row],[Total]]=0,"",(MAX(P$3:P7)+1)+MAX(Table1115[Line Number])) | Q8: Swing | R8: 32 | U8: =Table1116[[#This Row],[RH]]+Table1116[[#This Row],[LH]] -> 0 | Y8: 32 | Z8: =INT(Y8/12)&"' "&MOD(Y8,12)&"""" -> 2' 8" | AB8: =IF(Table18[[#This Row],[total]]=0,"",(MAX($AB$3:$AB7)+1)) | AC8: Swing | AD8: 32 | AE8: 80 | AF8: =Table11[[#This Row],[LH]] -> 0 | AG8: =Table11[[#This Row],[RH]] -> 0 | AH8: =Table18[[#This Row],[RH]]+Table18[[#This Row],[LH]] -> 0
B9: =IF(Table11[[#This Row],[Total]]=0,"",(MAX(B$3:B8)+1)) | C9: Swing | D9: 34 | G9: =Table11[[#This Row],[RH]]+Table11[[#This Row],[LH]] -> 0 | I9: =IF(Table1115[[#This Row],[Total]]=0,"",(MAX(I$3:I8)+1)+(MAX(Table11[Line Number]))) | J9: Swing | K9: 34 | N9: =Table1115[[#This Row],[RH]]+Table1115[[#This Row],[LH]] -> 0 | P9: =IF(Table1116[[#This Row],[Total]]=0,"",(MAX(P$3:P8)+1)+MAX(Table1115[Line Number])) | Q9: Swing | R9: 34 | U9: =Table1116[[#This Row],[RH]]+Table1116[[#This Row],[LH]] -> 0 | Y9: 34 | Z9: =INT(Y9/12)&"' "&MOD(Y9,12)&"""" -> 2' 10" | AB9: =IF(Table18[[#This Row],[total]]=0,"",(MAX($AB$3:$AB8)+1)) | AC9: Swing | AD9: 34 | AE9: 80 | AF9: =Table11[[#This Row],[LH]] -> 0 | AG9: =Table11[[#This Row],[RH]] -> 0 | AH9: =Table18[[#This Row],[RH]]+Table18[[#This Row],[LH]] -> 0
B10: =IF(Table11[[#This Row],[Total]]=0,"",(MAX(B$3:B9)+1)) | C10: Swing | D10: 36 | G10: =Table11[[#This Row],[RH]]+Table11[[#This Row],[LH]] -> 0 | I10: =IF(Table1115[[#This Row],[Total]]=0,"",(MAX(I$3:I9)+1)+(MAX(Table11[Line Number]))) | J10: Swing | K10: 36 | N10: =Table1115[[#This Row],[RH]]+Table1115[[#This Row],[LH]] -> 0 | P10: =IF(Table1116[[#This Row],[Total]]=0,"",(MAX(P$3:P9)+1)+MAX(Table1115[Line Number])) -> 7 | Q10: Swing | R10: 36 | T10: 1 | U10: =Table1116[[#This Row],[RH]]+Table1116[[#This Row],[LH]] -> 1 | Y10: 36 | Z10: =INT(Y10/12)&"' "&MOD(Y10,12)&"""" -> 3' 0" | AB10: =IF(Table18[[#This Row],[total]]=0,"",(MAX($AB$3:$AB9)+1)) | AC10: Swing | AD10: 36 | AE10: 80 | AF10: =Table11[[#This Row],[LH]] -> 0 | AG10: =Table11[[#This Row],[RH]] -> 0 | AH10: =Table18[[#This Row],[RH]]+Table18[[#This Row],[LH]] -> 0
B11: =IF(Table11[[#This Row],[Total]]=0,"",(MAX(B$3:B10)+1)) | C11: Bi-Fold | D11: 24 | G11: =Table11[[#This Row],[RH]]+Table11[[#This Row],[LH]] -> 0 | I11: =IF(Table1115[[#This Row],[Total]]=0,"",(MAX(I$3:I10)+1)+(MAX(Table11[Line Number]))) | J11: Bi-Fold | K11: 24 | N11: =Table1115[[#This Row],[RH]]+Table1115[[#This Row],[LH]] -> 0 | P11: =IF(Table1116[[#This Row],[Total]]=0,"",(MAX(P$3:P10)+1)+MAX(Table1115[Line Number])) | Q11: Bi-Fold | R11: 24 | U11: =Table1116[[#This Row],[RH]]+Table1116[[#This Row],[LH]] -> 0 | Y11: 48 | Z11: =INT(Y11/12)&"' "&MOD(Y11,12)&"""" -> 4' 0" | AB11: =IF(Table18[[#This Row],[total]]=0,"",(MAX($AB$3:$AB10)+1)) | AC11: Bi-Fold | AD11: 24 | AE11: 80 | AF11: =Table11[[#This Row],[LH]] -> 0 | AG11: =Table11[[#This Row],[RH]] -> 0 | AH11: =Table18[[#This Row],[RH]]+Table18[[#This Row],[LH]] -> 0
B12: =IF(Table11[[#This Row],[Total]]=0,"",(MAX(B$3:B11)+1)) | C12: Bi-Fold | D12: 26 | G12: =Table11[[#This Row],[RH]]+Table11[[#This Row],[LH]] -> 0 | I12: =IF(Table1115[[#This Row],[Total]]=0,"",(MAX(I$3:I11)+1)+(MAX(Table11[Line Number]))) | J12: Bi-Fold | K12: 26 | N12: =Table1115[[#This Row],[RH]]+Table1115[[#This Row],[LH]] -> 0 | P12: =IF(Table1116[[#This Row],[Total]]=0,"",(MAX(P$3:P11)+1)+MAX(Table1115[Line Number])) | Q12: Bi-Fold | R12: 26 | U12: =Table1116[[#This Row],[RH]]+Table1116[[#This Row],[LH]] -> 0 | Y12: 60 | Z12: =INT(Y12/12)&"' "&MOD(Y12,12)&"""" -> 5' 0" | AB12: =IF(Table18[[#This Row],[total]]=0,"",(MAX($AB$3:$AB11)+1)) | AC12: Bi-Fold | AD12: 26 | AE12: 80 | AF12: =Table11[[#This Row],[LH]] -> 0 | AG12: =Table11[[#This Row],[RH]] -> 0 | AH12: =Table18[[#This Row],[RH]]+Table18[[#This Row],[LH]] -> 0
B13: =IF(Table11[[#This Row],[Total]]=0,"",(MAX(B$3:B12)+1)) | C13: Bi-Fold | D13: 28 | G13: =Table11[[#This Row],[RH]]+Table11[[#This Row],[LH]] -> 0 | I13: =IF(Table1115[[#This Row],[Total]]=0,"",(MAX(I$3:I12)+1)+(MAX(Table11[Line Number]))) | J13: Bi-Fold | K13: 28 | N13: =Table1115[[#This Row],[RH]]+Table1115[[#This Row],[LH]] -> 0 | P13: =IF(Table1116[[#This Row],[Total]]=0,"",(MAX(P$3:P12)+1)+MAX(Table1115[Line Number])) | Q13: Bi-Fold | R13: 28 | U13: =Table1116[[#This Row],[RH]]+Table1116[[#This Row],[LH]] -> 0 | Y13: 72 | Z13: =INT(Y13/12)&"' "&MOD(Y13,12)&"""" -> 6' 0" | AB13: =IF(Table18[[#This Row],[total]]=0,"",(MAX($AB$3:$AB12)+1)) | AC13: Bi-Fold | AD13: 28 | AE13: 80 | AF13: =Table11[[#This Row],[LH]] -> 0 | AG13: =Table11[[#This Row],[RH]] -> 0 | AH13: =Table18[[#This Row],[RH]]+Table18[[#This Row],[LH]] -> 0
B14: =IF(Table11[[#This Row],[Total]]=0,"",(MAX(B$3:B13)+1)) | C14: Bi-Fold | D14: 30 | G14: =Table11[[#This Row],[RH]]+Table11[[#This Row],[LH]] -> 0 | I14: =IF(Table1115[[#This Row],[Total]]=0,"",(MAX(I$3:I13)+1)+(MAX(Table11[Line Number]))) | J14: Bi-Fold | K14: 30 | N14: =Table1115[[#This Row],[RH]]+Table1115[[#This Row],[LH]] -> 0 | P14: =IF(Table1116[[#This Row],[Total]]=0,"",(MAX(P$3:P13)+1)+MAX(Table1115[Line Number])) | Q14: Bi-Fold | R14: 30 | U14: =Table1116[[#This Row],[RH]]+Table1116[[#This Row],[LH]] -> 0 | Y14: 39 | Z14: =INT(Y14/12)&"' "&MOD(Y14,12)&"""" -> 3' 3" | AB14: =IF(Table18[[#This Row],[total]]=0,"",(MAX($AB$3:$AB13)+1)) | AC14: Bi-Fold | AD14: 30 | AE14: 80 | AF14: =Table11[[#This Row],[LH]] -> 0 | AG14: =Table11[[#This Row],[RH]] -> 0 | AH14: =Table18[[#This Row],[RH]]+Table18[[#This Row],[LH]] -> 0
B15: =IF(Table11[[#This Row],[Total]]=0,"",(MAX(B$3:B14)+1)) | C15: Bi-Fold | D15: 32 | G15: =Table11[[#This Row],[RH]]+Table11[[#This Row],[LH]] -> 0 | I15: =IF(Table1115[[#This Row],[Total]]=0,"",(MAX(I$3:I14)+1)+(MAX(Table11[Line Number]))) | J15: Bi-Fold | K15: 32 | N15: =Table1115[[#This Row],[RH]]+Table1115[[#This Row],[LH]] -> 0 | P15: =IF(Table1116[[#This Row],[Total]]=0,"",(MAX(P$3:P14)+1)+MAX(Table1115[Line Number])) | Q15: Bi-Fold | R15: 32 | U15: =Table1116[[#This Row],[RH]]+Table1116[[#This Row],[LH]] -> 0 | Y15: 42 | Z15: =INT(Y15/12)&"' "&MOD(Y15,12)&"""" -> 3' 6" | AB15: =IF(Table18[[#This Row],[total]]=0,"",(MAX($AB$3:$AB14)+1)) | AC15: Bi-Fold | AD15: 32 | AE15: 80 | AF15: =Table11[[#This Row],[LH]] -> 0 | AG15: =Table11[[#This Row],[RH]] -> 0 | AH15: =Table18[[#This Row],[RH]]+Table18[[#This Row],[LH]] -> 0
B16: =IF(Table11[[#This Row],[Total]]=0,"",(MAX(B$3:B15)+1)) | C16: Bi-Fold | D16: 34 | G16: =Table11[[#This Row],[RH]]+Table11[[#This Row],[LH]] -> 0 | I16: =IF(Table1115[[#This Row],[Total]]=0,"",(MAX(I$3:I15)+1)+(MAX(Table11[Line Number]))) | J16: Bi-Fold | K16: 34 | N16: =Table1115[[#This Row],[RH]]+Table1115[[#This Row],[LH]] -> 0 | P16: =IF(Table1116[[#This Row],[Total]]=0,"",(MAX(P$3:P15)+1)+MAX(Table1115[Line Number])) | Q16: Bi-Fold | R16: 34 | U16: =Table1116[[#This Row],[RH]]+Table1116[[#This Row],[LH]] -> 0 | Y16: 45 | Z16: =INT(Y16/12)&"' "&MOD(Y16,12)&"""" -> 3' 9" | AB16: =IF(Table18[[#This Row],[total]]=0,"",(MAX($AB$3:$AB15)+1)) | AC16: Bi-Fold | AD16: 34 | AE16: 80 | AF16: =Table11[[#This Row],[LH]] -> 0 | AG16: =Table11[[#This Row],[RH]] -> 0 | AH16: =Table18[[#This Row],[RH]]+Table18[[#This Row],[LH]] -> 0
B17: =IF(Table11[[#This Row],[Total]]=0,"",(MAX(B$3:B16)+1)) | C17: Bi-Fold | D17: 36 | G17: =Table11[[#This Row],[RH]]+Table11[[#This Row],[LH]] -> 0 | I17: =IF(Table1115[[#This Row],[Total]]=0,"",(MAX(I$3:I16)+1)+(MAX(Table11[Line Number]))) | J17: Bi-Fold | K17: 36 | N17: =Table1115[[#This Row],[RH]]+Table1115[[#This Row],[LH]] -> 0 | P17: =IF(Table1116[[#This Row],[Total]]=0,"",(MAX(P$3:P16)+1)+MAX(Table1115[Line Number])) | Q17: Bi-Fold | R17: 36 | U17: =Table1116[[#This Row],[RH]]+Table1116[[#This Row],[LH]] -> 0 | Y17: 80 | Z17: =INT(Y17/12)&"' "&MOD(Y17,12)&"""" -> 6' 8" | AB17: =IF(Table18[[#This Row],[total]]=0,"",(MAX($AB$3:$AB16)+1)) | AC17: Bi-Fold | AD17: 36 | AE17: 80 | AF17: =Table11[[#This Row],[LH]] -> 0 | AG17: =Table11[[#This Row],[RH]] -> 0 | AH17: =Table18[[#This Row],[RH]]+Table18[[#This Row],[LH]] -> 0
B18: =IF(Table11[[#This Row],[Total]]=0,"",(MAX(B$3:B17)+1)) | C18: Bi-Pass | D18: 48 | G18: =Table11[[#This Row],[RH]]+Table11[[#This Row],[LH]] -> 0 | I18: =IF(Table1115[[#This Row],[Total]]=0,"",(MAX(I$3:I17)+1)+(MAX(Table11[Line Number]))) | J18: Bi-Pass | K18: 48 | N18: =Table1115[[#This Row],[RH]]+Table1115[[#This Row],[LH]] -> 0 | P18: =IF(Table1116[[#This Row],[Total]]=0,"",(MAX(P$3:P17)+1)+MAX(Table1115[Line Number])) | Q18: Bi-Pass | R18: 48 | U18: =Table1116[[#This Row],[RH]]+Table1116[[#This Row],[LH]] -> 0 | Y18: 84 | Z18: =INT(Y18/12)&"' "&MOD(Y18,12)&"""" -> 7' 0" | AB18: =IF(Table18[[#This Row],[total]]=0,"",(MAX($AB$3:$AB17)+1)) | AC18: Bi-Pass | AD18: 48 | AE18: 80 | AF18: =Table11[[#This Row],[LH]] -> 0 | AG18: =Table11[[#This Row],[RH]] -> 0 | AH18: =Table18[[#This Row],[RH]]+Table18[[#This Row],[LH]] -> 0
B19: =IF(Table11[[#This Row],[Total]]=0,"",(MAX(B$3:B18)+1)) | C19: Bi-Pass | D19: 60 | G19: =Table11[[#This Row],[RH]]+Table11[[#This Row],[LH]] -> 0 | I19: =IF(Table1115[[#This Row],[Total]]=0,"",(MAX(I$3:I18)+1)+(MAX(Table11[Line Number]))) | J19: Bi-Pass | K19: 60 | N19: =Table1115[[#This Row],[RH]]+Table1115[[#This Row],[LH]] -> 0 | P19: =IF(Table1116[[#This Row],[Total]]=0,"",(MAX(P$3:P18)+1)+MAX(Table1115[Line Number])) | Q19: Bi-Pass | R19: 60 | U19: =Table1116[[#This Row],[RH]]+Table1116[[#This Row],[LH]] -> 0 | Y19: 96 | Z19: =INT(Y19/12)&"' "&MOD(Y19,12)&"""" -> 8' 0" | AB19: =IF(Table18[[#This Row],[total]]=0,"",(MAX($AB$3:$AB18)+1)) | AC19: Bi-Pass | AD19: 60 | AE19: 80 | AF19: =Table11[[#This Row],[LH]] -> 0 | AG19: =Table11[[#This Row],[RH]] -> 0 | AH19: =Table18[[#This Row],[RH]]+Table18[[#This Row],[LH]] -> 0
B20: =IF(Table11[[#This Row],[Total]]=0,"",(MAX(B$3:B19)+1)) | C20: Bi-Pass | D20: 72 | G20: =Table11[[#This Row],[RH]]+Table11[[#This Row],[LH]] -> 0 | I20: =IF(Table1115[[#This Row],[Total]]=0,"",(MAX(I$3:I19)+1)+(MAX(Table11[Line Number]))) | J20: Bi-Pass | K20: 72 | N20: =Table1115[[#This Row],[RH]]+Table1115[[#This Row],[LH]] -> 0 | P20: =IF(Table1116[[#This Row],[Total]]=0,"",(MAX(P$3:P19)+1)+MAX(Table1115[Line Number])) | Q20: Bi-Pass | R20: 72 | U20: =Table1116[[#This Row],[RH]]+Table1116[[#This Row],[LH]] -> 0 | AB20: =IF(Table18[[#This Row],[total]]=0,"",(MAX($AB$3:$AB19)+1)) | AC20: Bi-Pass | AD20: 72 | AE20: 80 | AF20: =Table11[[#This Row],[LH]] -> 0 | AG20: =Table11[[#This Row],[RH]] -> 0 | AH20: =Table18[[#This Row],[RH]]+Table18[[#This Row],[LH]] -> 0
B21: =IF(Table11[[#This Row],[Total]]=0,"",(MAX(B$3:B20)+1)) | C21: Pocket | D21: 24 | G21: =Table11[[#This Row],[RH]]+Table11[[#This Row],[LH]] -> 0 | I21: =IF(Table1115[[#This Row],[Total]]=0,"",(MAX(I$3:I20)+1)+(MAX(Table11[Line Number]))) | J21: Pocket | K21: 24 | N21: =Table1115[[#This Row],[RH]]+Table1115[[#This Row],[LH]] -> 0 | P21: =IF(Table1116[[#This Row],[Total]]=0,"",(MAX(P$3:P20)+1)+MAX(Table1115[Line Number])) | Q21: Pocket | R21: 24 | U21: =Table1116[[#This Row],[RH]]+Table1116[[#This Row],[LH]] -> 0 | AB21: =IF(Table18[[#This Row],[total]]=0,"",(MAX($AB$3:$AB20)+1)) | AC21: Pocket | AD21: 24 | AE21: 80 | AF21: =Table11[[#This Row],[LH]] -> 0 | AG21: =Table11[[#This Row],[RH]] -> 0 | AH21: =Table18[[#This Row],[RH]]+Table18[[#This Row],[LH]] -> 0
B22: =IF(Table11[[#This Row],[Total]]=0,"",(MAX(B$3:B21)+1)) | C22: Pocket | D22: 26 | G22: =Table11[[#This Row],[RH]]+Table11[[#This Row],[LH]] -> 0 | I22: =IF(Table1115[[#This Row],[Total]]=0,"",(MAX(I$3:I21)+1)+(MAX(Table11[Line Number]))) | J22: Pocket | K22: 26 | N22: =Table1115[[#This Row],[RH]]+Table1115[[#This Row],[LH]] -> 0 | P22: =IF(Table1116[[#This Row],[Total]]=0,"",(MAX(P$3:P21)+1)+MAX(Table1115[Line Number])) | Q22: Pocket | R22: 26 | U22: =Table1116[[#This Row],[RH]]+Table1116[[#This Row],[LH]] -> 0 | AB22: =IF(Table18[[#This Row],[total]]=0,"",(MAX($AB$3:$AB21)+1)) | AC22: Pocket | AD22: 26 | AE22: 80 | AF22: =Table11[[#This Row],[LH]] -> 0 | AG22: =Table11[[#This Row],[RH]] -> 0 | AH22: =Table18[[#This Row],[RH]]+Table18[[#This Row],[LH]] -> 0
B23: =IF(Table11[[#This Row],[Total]]=0,"",(MAX(B$3:B22)+1)) | C23: Pocket | D23: 28 | G23: =Table11[[#This Row],[RH]]+Table11[[#This Row],[LH]] -> 0 | I23: =IF(Table1115[[#This Row],[Total]]=0,"",(MAX(I$3:I22)+1)+(MAX(Table11[Line Number]))) | J23: Pocket | K23: 28 | N23: =Table1115[[#This Row],[RH]]+Table1115[[#This Row],[LH]] -> 0 | P23: =IF(Table1116[[#This Row],[Total]]=0,"",(MAX(P$3:P22)+1)+MAX(Table1115[Line Number])) | Q23: Pocket | R23: 28 | U23: =Table1116[[#This Row],[RH]]+Table1116[[#This Row],[LH]] -> 0 | AB23: =IF(Table18[[#This Row],[total]]=0,"",(MAX($AB$3:$AB22)+1)) | AC23: Pocket | AD23: 28 | AE23: 80 | AF23: =Table11[[#This Row],[LH]] -> 0 | AG23: =Table11[[#This Row],[RH]] -> 0 | AH23: =Table18[[#This Row],[RH]]+Table18[[#This Row],[LH]] -> 0
B24: =IF(Table11[[#This Row],[Total]]=0,"",(MAX(B$3:B23)+1)) | C24: Pocket | D24: 30 | G24: =Table11[[#This Row],[RH]]+Table11[[#This Row],[LH]] -> 0 | I24: =IF(Table1115[[#This Row],[Total]]=0,"",(MAX(I$3:I23)+1)+(MAX(Table11[Line Number]))) | J24: Pocket | K24: 30 | N24: =Table1115[[#This Row],[RH]]+Table1115[[#This Row],[LH]] -> 0 | P24: =IF(Table1116[[#This Row],[Total]]=0,"",(MAX(P$3:P23)+1)+MAX(Table1115[Line Number])) | Q24: Pocket | R24: 30 | U24: =Table1116[[#This Row],[RH]]+Table1116[[#This Row],[LH]] -> 0 | AB24: =IF(Table18[[#This Row],[total]]=0,"",(MAX($AB$3:$AB23)+1)) | AC24: Pocket | AD24: 30 | AE24: 80 | AF24: =Table11[[#This Row],[LH]] -> 0 | AG24: =Table11[[#This Row],[RH]] -> 0 | AH24: =Table18[[#This Row],[RH]]+Table18[[#This Row],[LH]] -> 0
B25: =IF(Table11[[#This Row],[Total]]=0,"",(MAX(B$3:B24)+1)) | C25: Pocket | D25: 32 | G25: =Table11[[#This Row],[RH]]+Table11[[#This Row],[LH]] -> 0 | I25: =IF(Table1115[[#This Row],[Total]]=0,"",(MAX(I$3:I24)+1)+(MAX(Table11[Line Number]))) | J25: Pocket | K25: 32 | N25: =Table1115[[#This Row],[RH]]+Table1115[[#This Row],[LH]] -> 0 | P25: =IF(Table1116[[#This Row],[Total]]=0,"",(MAX(P$3:P24)+1)+MAX(Table1115[Line Number])) | Q25: Pocket | R25: 32 | U25: =Table1116[[#This Row],[RH]]+Table1116[[#This Row],[LH]] -> 0 | AB25: =IF(Table18[[#This Row],[total]]=0,"",(MAX($AB$3:$AB24)+1)) | AC25: Pocket | AD25: 32 | AE25: 80 | AF25: =Table11[[#This Row],[LH]] -> 0 | AG25: =Table11[[#This Row],[RH]] -> 0 | AH25: =Table18[[#This Row],[RH]]+Table18[[#This Row],[LH]] -> 0
B26: =IF(Table11[[#This Row],[Total]]=0,"",(MAX(B$3:B25)+1)) | C26: Pocket | D26: 34 | G26: =Table11[[#This Row],[RH]]+Table11[[#This Row],[LH]] -> 0 | I26: =IF(Table1115[[#This Row],[Total]]=0,"",(MAX(I$3:I25)+1)+(MAX(Table11[Line Number]))) | J26: Pocket | K26: 34 | N26: =Table1115[[#This Row],[RH]]+Table1115[[#This Row],[LH]] -> 0 | P26: =IF(Table1116[[#This Row],[Total]]=0,"",(MAX(P$3:P25)+1)+MAX(Table1115[Line Number])) | Q26: Pocket | R26: 34 | U26: =Table1116[[#This Row],[RH]]+Table1116[[#This Row],[LH]] -> 0 | AB26: =IF(Table18[[#This Row],[total]]=0,"",(MAX($AB$3:$AB25)+1)) | AC26: Pocket | AD26: 34 | AE26: 80 | AF26: =Table11[[#This Row],[LH]] -> 0 | AG26: =Table11[[#This Row],[RH]] -> 0 | AH26: =Table18[[#This Row],[RH]]+Table18[[#This Row],[LH]] -> 0
B27: =IF(Table11[[#This Row],[Total]]=0,"",(MAX(B$3:B26)+1)) | C27: Pocket | D27: 36 | G27: =Table11[[#This Row],[RH]]+Table11[[#This Row],[LH]] -> 0 | I27: =IF(Table1115[[#This Row],[Total]]=0,"",(MAX(I$3:I26)+1)+(MAX(Table11[Line Number]))) | J27: Pocket | K27: 36 | N27: =Table1115[[#This Row],[RH]]+Table1115[[#This Row],[LH]] -> 0 | P27: =IF(Table1116[[#This Row],[Total]]=0,"",(MAX(P$3:P26)+1)+MAX(Table1115[Line Number])) | Q27: Pocket | R27: 36 | U27: =Table1116[[#This Row],[RH]]+Table1116[[#This Row],[LH]] -> 0 | AB27: =IF(Table18[[#This Row],[total]]=0,"",(MAX($AB$3:$AB26)+1)) | AC27: Pocket | AD27: 36 | AE27: 80 | AF27: =Table11[[#This Row],[LH]] -> 0 | AG27: =Table11[[#This Row],[RH]] -> 0 | AH27: =Table18[[#This Row],[RH]]+Table18[[#This Row],[LH]] -> 0
B28: =IF(Table11[[#This Row],[Total]]=0,"",(MAX(B$3:B27)+1)) | C28: Barn | D28: 30 | G28: =Table11[[#This Row],[RH]]+Table11[[#This Row],[LH]] -> 0 | I28: =IF(Table1115[[#This Row],[Total]]=0,"",(MAX(I$3:I27)+1)+(MAX(Table11[Line Number]))) | J28: Barn | K28: 30 | N28: =Table1115[[#This Row],[RH]]+Table1115[[#This Row],[LH]] -> 0 | P28: =IF(Table1116[[#This Row],[Total]]=0,"",(MAX(P$3:P27)+1)+MAX(Table1115[Line Number])) | Q28: Barn | R28: 30 | U28: =Table1116[[#This Row],[RH]]+Table1116[[#This Row],[LH]] -> 0 | AB28: =IF(Table18[[#This Row],[total]]=0,"",(MAX($AB$3:$AB27)+1)) | AC28: Barn | AD28: 30 | AE28: 80 | AF28: =Table11[[#This Row],[LH]] -> 0 | AG28: =Table11[[#This Row],[RH]] -> 0 | AH28: =Table18[[#This Row],[RH]]+Table18[[#This Row],[LH]] -> 0
B29: =IF(Table11[[#This Row],[Total]]=0,"",(MAX(B$3:B28)+1)) | C29: Barn | D29: 32 | G29: =Table11[[#This Row],[RH]]+Table11[[#This Row],[LH]] -> 0 | I29: =IF(Table1115[[#This Row],[Total]]=0,"",(MAX(I$3:I28)+1)+(MAX(Table11[Line Number]))) | J29: Barn | K29: 32 | N29: =Table1115[[#This Row],[RH]]+Table1115[[#This Row],[LH]] -> 0 | P29: =IF(Table1116[[#This Row],[Total]]=0,"",(MAX(P$3:P28)+1)+MAX(Table1115[Line Number])) | Q29: Barn | R29: 32 | U29: =Table1116[[#This Row],[RH]]+Table1116[[#This Row],[LH]] -> 0 | AB29: =IF(Table18[[#This Row],[total]]=0,"",(MAX($AB$3:$AB28)+1)) | AC29: Barn | AD29: 32 | AE29: 80 | AF29: =Table11[[#This Row],[LH]] -> 0 | AG29: =Table11[[#This Row],[RH]] -> 0 | AH29: =Table18[[#This Row],[RH]]+Table18[[#This Row],[LH]] -> 0
B30: =IF(Table11[[#This Row],[Total]]=0,"",(MAX(B$3:B29)+1)) | C30: Barn | D30: 34 | G30: =Table11[[#This Row],[RH]]+Table11[[#This Row],[LH]] -> 0 | I30: =IF(Table1115[[#This Row],[Total]]=0,"",(MAX(I$3:I29)+1)+(MAX(Table11[Line Number]))) | J30: Barn | K30: 34 | N30: =Table1115[[#This Row],[RH]]+Table1115[[#This Row],[LH]] -> 0 | P30: =IF(Table1116[[#This Row],[Total]]=0,"",(MAX(P$3:P29)+1)+MAX(Table1115[Line Number])) | Q30: Barn | R30: 34 | U30: =Table1116[[#This Row],[RH]]+Table1116[[#This Row],[LH]] -> 0 | AB30: =IF(Table18[[#This Row],[total]]=0,"",(MAX($AB$3:$AB29)+1)) | AC30: Barn | AD30: 34 | AE30: 80 | AF30: =Table11[[#This Row],[LH]] -> 0 | AG30: =Table11[[#This Row],[RH]] -> 0 | AH30: =Table18[[#This Row],[RH]]+Table18[[#This Row],[LH]] -> 0
B31: =IF(Table11[[#This Row],[Total]]=0,"",(MAX(B$3:B30)+1)) | C31: Barn | D31: 36 | G31: =Table11[[#This Row],[RH]]+Table11[[#This Row],[LH]] -> 0 | I31: =IF(Table1115[[#This Row],[Total]]=0,"",(MAX(I$3:I30)+1)+(MAX(Table11[Line Number]))) | J31: Barn | K31: 36 | N31: =Table1115[[#This Row],[RH]]+Table1115[[#This Row],[LH]] -> 0 | P31: =IF(Table1116[[#This Row],[Total]]=0,"",(MAX(P$3:P30)+1)+MAX(Table1115[Line Number])) | Q31: Barn | R31: 36 | U31: =Table1116[[#This Row],[RH]]+Table1116[[#This Row],[LH]] -> 0 | AB31: =IF(Table18[[#This Row],[total]]=0,"",(MAX($AB$3:$AB30)+1)) | AC31: Barn | AD31: 36 | AE31: 80 | AF31: =Table11[[#This Row],[LH]] -> 0 | AG31: =Table11[[#This Row],[RH]] -> 0 | AH31: =Table18[[#This Row],[RH]]+Table18[[#This Row],[LH]] -> 0
... B35: =IF(Table11[[#This Row],[Total]]=0,"",(MAX(B$3:B34)+1)) | C35: Barn | D35: 48 | G35: =Table11[[#This Row],[RH]]+Table11[[#This Row],[LH]] -> 0 | I35: =IF(Table1115[[#This Row],[Total]]=0,"",(MAX(I$3:I34)+1)+(MAX(Table11[Line Number]))) | J35: Barn | K35: 48 | N35: =Table1115[[#This Row],[RH]]+Table1115[[#This Row],[LH]] -> 0 | P35: =IF(Table1116[[#This Row],[Total]]=0,"",(MAX(P$3:P34)+1)+MAX(Table1115[Line Number])) | Q35: Barn | R35: 48 | U35: =Table1116[[#This Row],[RH]]+Table1116[[#This Row],[LH]] -> 0 | AB35: =IF(Table18[[#This Row],[total]]=0,"",(MAX($AB$3:$AB34)+1)) | AC35: Barn | AD35: 48 | AE35: 80 | AF35: =Table11[[#This Row],[LH]] -> 0 | AG35: =Table11[[#This Row],[RH]] -> 0 | AH35: =Table18[[#This Row],[RH]]+Table18[[#This Row],[LH]] -> 0
AB36: =IF(Table18[[#This Row],[total]]=0,"",(MAX($AB$3:$AB35)+1)) | AC36: Swing | AD36: 24 | AE36: 84 | AF36: =L4 -> 0 | AG36: =M4 -> 0 | AH36: =Table18[[#This Row],[RH]]+Table18[[#This Row],[LH]] -> 0
AB37: =IF(Table18[[#This Row],[total]]=0,"",(MAX($AB$3:$AB36)+1)) | AC37: Swing | AD37: 26 | AE37: 84 | AF37: =L5 -> 0 | AG37: =M5 -> 0 | AH37: =Table18[[#This Row],[RH]]+Table18[[#This Row],[LH]] -> 0
AB38: =IF(Table18[[#This Row],[total]]=0,"",(MAX($AB$3:$AB37)+1)) | AC38: Swing | AD38: 28 | AE38: 84 | AF38: =L6 -> 0 | AG38: =M6 -> 0 | AH38: =Table18[[#This Row],[RH]]+Table18[[#This Row],[LH]] -> 0
AB39: =IF(Table18[[#This Row],[total]]=0,"",(MAX($AB$3:$AB38)+1)) -> 3 | AC39: Swing | AD39: 30 | AE39: 84 | AF39: =L7 -> 3 | AG39: =M7 -> 0 | AH39: =Table18[[#This Row],[RH]]+Table18[[#This Row],[LH]] -> 3
AB40: =IF(Table18[[#This Row],[total]]=0,"",(MAX($AB$3:$AB39)+1)) -> 4 | AC40: Swing | AD40: 32 | AE40: 84 | AF40: =L8 -> 2 | AG40: =M8 -> 0 | AH40: =Table18[[#This Row],[RH]]+Table18[[#This Row],[LH]] -> 2
AB41: =IF(Table18[[#This Row],[total]]=0,"",(MAX($AB$3:$AB40)+1)) | AC41: Swing | AD41: 34 | AE41: 84 | AF41: =L9 -> 0 | AG41: =M9 -> 0 | AH41: =Table18[[#This Row],[RH]]+Table18[[#This Row],[LH]] -> 0
AB42: =IF(Table18[[#This Row],[total]]=0,"",(MAX($AB$3:$AB41)+1)) | AC42: Swing | AD42: 36 | AE42: 84 | AF42: =L10 -> 0 | AG42: =M10 -> 0 | AH42: =Table18[[#This Row],[RH]]+Table18[[#This Row],[LH]] -> 0
AB43: =IF(Table18[[#This Row],[total]]=0,"",(MAX($AB$3:$AB42)+1)) | AC43: Bi-Fold | AD43: 24 | AE43: 84 | AF43: =L11 -> 0 | AG43: =M11 -> 0 | AH43: =Table18[[#This Row],[RH]]+Table18[[#This Row],[LH]] -> 0
